Workbook
Name Slicer_MONTH: #N/A
Name Slicer_REGION: #N/A

Sheet Input Data
A1: DATE | B1: CUSTOMER NAME | C1: PRODUCT | D1: UNIT PRICE ($) | E1: QUANTITY | F1: TOTAL SALES | G1: COUNTRY | H1: REGION | I1: MONTH | J1: WEEK
A2: 44197 | B2: Customer33 | C2: Product24 | D2: 156.96 | E2: 9 | F2: =InputData[[#This Row],[UNIT PRICE ($)]]*InputData[[#This Row],[QUANTITY]] -> 1412.64 | G2: =VLOOKUP(InputData[[#This Row],[CUSTOMER NAME]],Country[],2,0) -> India | H2: =VLOOKUP(InputData[[#This Row],[CUSTOMER NAME]],Country[],3,0) -> Western | I2: =TEXT(InputData[[#This Row],[DATE]],"MMM") -> Jan | J2: =WEEKNUM(InputData[[#This Row],[DATE]]) -> 1
A3: 44197 | B3: Customer29 | C3: Product22 | D3: 141.57 | E3: 1 | F3: =InputData[[#This Row],[UNIT PRICE ($)]]*InputData[[#This Row],[QUANTITY]] -> 141.57 | G3: =VLOOKUP(InputData[[#This Row],[CUSTOMER NAME]],Country[],2,0) -> India | H3: =VLOOKUP(InputData[[#This Row],[CUSTOMER NAME]],Country[],3,0) -> South | I3: =TEXT(InputData[[#This Row],[DATE]],"MMM") -> Jan | J3: =WEEKNUM(InputData[[#This Row],[DATE]]) -> 1
A4: 44198 | B4: Customer31 | C4: Product38 | D4: 79.92 | E4: 15 | F4: =InputData[[#This Row],[UNIT PRICE ($)]]*InputData[[#This Row],[QUANTITY]] -> 1198.8 | G4: =VLOOKUP(InputData[[#This Row],[CUSTOMER NAME]],Country[],2,0) -> India | H4: =VLOOKUP(InputData[[#This Row],[CUSTOMER NAME]],Country[],3,0) -> North | I4: =TEXT(InputData[[#This Row],[DATE]],"MMM") -> Jan | J4: =WEEKNUM(InputData[[#This Row],[DATE]]) -> 1
A5: 44198 | B5: Customer03 | C5: Product33 | D5: 119.7 | E5: 1 | F5: =InputData[[#This Row],[UNIT PRICE ($)]]*InputData[[#This Row],[QUANTITY]] -> 119.7 | G5: =VLOOKUP(InputData[[#This Row],[CUSTOMER NAME]],Country[],2,0) -> India | H5: =VLOOKUP(InputData[[#This Row],[CUSTOMER NAME]],Country[],3,0) -> Northeast | I5: =TEXT(InputData[[#This Row],[DATE]],"MMM") -> Jan | J5: =WEEKNUM(InputData[[#This Row],[DATE]]) -> 1
A6: 44198 | B6: Customer05 | C6: Product15 | D6: 15.72 | E6: 2 | F6: =InputData[[#This Row],[UNIT PRICE ($)]]*InputData[[#This Row],[QUANTITY]] -> 31.44 | G6: =VLOOKUP(InputData[[#This Row],[CUSTOMER NAME]],Country[],2,0) -> India | H6: =VLOOKUP(InputData[[#This Row],[CUSTOMER NAME]],Country[],3,0) -> Northeast | I6: =TEXT(InputData[[#This Row],[DATE]],"MMM") -> Jan | J6: =WEEKNUM(InputData[[#This Row],[DATE]]) -> 1
A7: 44198 | B7: Customer35 | C7: Product10 | D7: 164.28 | E7: 7 | F7: =InputData[[#This Row],[UNIT PRICE ($)]]*InputData[[#This Row],[QUANTITY]] -> 1149.96 | G7: =VLOOKUP(InputData[[#This Row],[CUSTOMER NAME]],Country[],2,0) -> India | H7: =VLOOKUP(InputData[[#This Row],[CUSTOMER NAME]],Country[],3,0) -> North | I7: =TEXT(InputData[[#This Row],[DATE]],"MMM") -> Jan | J7: =WEEKNUM(InputData[[#This Row],[DATE]]) -> 1
A8: 44198 | B8: Customer38 | C8: Product13 | D8: 122.08 | E8: 6 | F8: =InputData[[#This Row],[UNIT PRICE ($)]]*InputData[[#This Row],[QUANTITY]] -> 732.48 | G8: =VLOOKUP(InputData[[#This Row],[CUSTOMER NAME]],Country[],2,0) -> India | H8: =VLOOKUP(InputData[[#This Row],[CUSTOMER NAME]],Country[],3,0) -> Northeast | I8: =TEXT(InputData[[#This Row],[DATE]],"MMM") -> Jan | J8: =WEEKNUM(InputData[[#This Row],[DATE]]) -> 1
A9: 44198 | B9: Customer39 | C9: Product15 | D9: 15.72 | E9: 25 | F9: =InputData[[#This Row],[UNIT PRICE ($)]]*InputData[[#This Row],[QUANTITY]] -> 393 | G9: =VLOOKUP(InputData[[#This Row],[CUSTOMER NAME]],Country[],2,0) -> Germany | H9: =VLOOKUP(InputData[[#This Row],[CUSTOMER NAME]],Country[],3,0) -> Export | I9: =TEXT(InputData[[#This Row],[DATE]],"MMM") -> Jan | J9: =WEEKNUM(InputData[[#This Row],[DATE]]) -> 1
A10: 44199 | B10: Customer34 | C10: Product14 | D10: 146.72 | E10: 21 | F10: =InputData[[#This Row],[UNIT PRICE ($)]]*InputData[[#This Row],[QUANTITY]] -> 3081.12 | G10: =VLOOKUP(InputData[[#This Row],[CUSTOMER NAME]],Country[],2,0) -> India | H10: =VLOOKUP(InputData[[#This Row],[CUSTOMER NAME]],Country[],3,0) -> Northeast | I10: =TEXT(InputData[[#This Row],[DATE]],"MMM") -> Jan | J10: =WEEKNUM(InputData[[#This Row],[DATE]]) -> 2
A11: 44199 | B11: Customer18 | C11: Product43 | D11: 83.08 | E11: 9 | F11: =InputData[[#This Row],[UNIT PRICE ($)]]*InputData[[#This Row],[QUANTITY]] -> 747.72 | G11: =VLOOKUP(InputData[[#This Row],[CUSTOMER NAME]],Country[],2,0) -> India | H11: =VLOOKUP(InputData[[#This Row],[CUSTOMER NAME]],Country[],3,0) -> Western | I11: =TEXT(InputData[[#This Row],[DATE]],"MMM") -> Jan | J11: =WEEKNUM(InputData[[#This Row],[DATE]]) -> 2
A12: 44199 | B12: Customer20 | C12: Product38 | D12: 79.92 | E12: 31 | F12: =InputData[[#This Row],[UNIT PRICE ($)]]*InputData[[#This Row],[QUANTITY]] -> 2477.52 | G12: =VLOOKUP(InputData[[#This Row],[CUSTOMER NAME]],Country[],2,0) -> United Kingdom | H12: =VLOOKUP(InputData[[#This Row],[CUSTOMER NAME]],Country[],3,0) -> Export | I12: =TEXT(InputData[[#This Row],[DATE]],"MMM") -> Jan | J12: =WEEKNUM(InputData[[#This Row],[DATE]]) -> 2
A13: 44199 | B13: Customer37 | C13: Product04 | D13: 48.84 | E13: 5 | F13: =InputData[[#This Row],[UNIT PRICE ($)]]*InputData[[#This Row],[QUANTITY]] -> 244.2 | G13: =VLOOKUP(InputData[[#This Row],[CUSTOMER NAME]],Country[],2,0) -> United States of America | H13: =VLOOKUP(InputData[[#This Row],[CUSTOMER NAME]],Country[],3,0) -> Export | I13: =TEXT(InputData[[#This Row],[DATE]],"MMM") -> Jan | J13: =WEEKNUM(InputData[[#This Row],[DATE]]) -> 2
... A833: 44561 | B833: Customer18 | C833: Product33 | D833: 119.7 | E833: 12 | F833: =InputData[[#This Row],[UNIT PRICE ($)]]*InputData[[#This Row],[QUANTITY]] -> 1436.4 | G833: =VLOOKUP(InputData[[#This Row],[CUSTOMER NAME]],Country[],2,0) -> India | H833: =VLOOKUP(InputData[[#This Row],[CUSTOMER NAME]],Country[],3,0) -> Western | I833: =TEXT(InputData[[#This Row],[DATE]],"MMM") -> Dec | J833: =WEEKNUM(InputData[[#This Row],[DATE]]) -> 53

Sheet Analysis
A1: Sum of TOTAL SALES | D1: Row Labels | E1: Sum of TOTAL SALES | G1: Row Labels | H1: Sum of TOTAL SALES | J1: Row Labels | K1: Sum of TOTAL SALES | M1: Row Labels | N1: Sum of TOTAL SALES | P1: Row Labels | Q1: Sum of TOTAL SALES | T1: Row Labels | U1: Sum of TOTAL SALES
A2: 984571.06 | D2: Jan | E2: 92118.79 | G2: 1 | H2: 5179.59 | J2: Customer33 | K2: 60929.15 | M2: Product30 | N2: 57968.64 | P2: Bangladesh | Q2: 31336.23 | T2: Central | U2: 72920.48
D3: Feb | E3: 91137.05 | G3: 2 | H3: 21116.73 | J3: Customer22 | K3: 45112.95 | M3: Product41 | N3: 57554.28 | P3: Brazil | Q3: 39438.44 | T3: East | U3: 75939.73
A4: =GETPIVOTDATA("TOTAL SALES",$A$1) -> 984571.06 | D4: Mar | E4: 97920.72 | G4: 3 | H4: 14261.19 | J4: Customer23 | K4: 43062.83 | M4: Product24 | N4: 49599.36 | P4: Ethiopia | Q4: 39653.93 | T4: Export | U4: 531575.62
D5: Apr | E5: 72320.89 | G5: 4 | H5: 11433.2 | M5: Product19 | N5: 41580 | P5: France | Q5: 14337.4 | T5: North | U5: 45081.78
D6: May | E6: 70511.76 | G6: 5 | H6: 33727.55 | J6: Column1 | K6: Column2 | M6: Product22 | N6: 41055.3 | P6: Germany | Q6: 16810.72 | T6: Northeast | U6: 83994.49
D7: Jun | E7: 66727.4 | G7: 6 | H7: 34794.82 | J7: =J2 -> Customer33 | K7: =K2 -> 60929.15 | M7: Product32 | N7: 40883.04 | P7: India | Q7: 452995.44 | T7: South | U7: 53277.57
D8: Jul | E8: 92661.55 | G8: 7 | H8: 32107.1 | J8: =J3 -> Customer22 | K8: =K3 -> 45112.95 | M8: Product21 | N8: 39659.76 | P8: Indonesia | Q8: 8394.32 | T8: Western | U8: 121781.39
D9: Aug | E9: 69125.75 | G9: 8 | H9: 11777.67 | J9: =J4 -> Customer23 | K9: =K4 -> 43062.83 | M9: Product05 | N9: 38591.28 | P9: Mexico | Q9: 65776.76
D10: Sep | E10: 78253.53 | G10: 9 | H10: 17571.59 | M10: Product42 | N10: 38232 | P10: Nigeria | Q10: 39993.27
D11: Oct | E11: 87136.37 | G11: 10 | H11: 17413.3 | M11: Product10 | N11: 34991.64 | P11: Pakistan | Q11: 77523.28
D12: Nov | E12: 75659.86 | G12: 11 | H12: 18811.39 | P12: Russia | Q12: 63344.34
D13: Dec | E13: 90997.39 | G13: 12 | H13: 29446.46 | P13: Saudi Arabia | Q13: 38317.79
G14: 13 | H14: 22723.6 | P14: South Africa | Q14: 32808.02
G15: 14 | H15: 13729.81 | P15: United Kingdom | Q15: 50749.04
G16: 15 | H16: 27820.09 | P16: United States of America | Q16: 13092.08
G17: 16 | H17: 9407.51
G18: 17 | H18: 22127.3
G19: 18 | H19: 11809.4 | P19: =P2 -> Bangladesh | Q19: =Q2 -> 31336.23
G20: 19 | H20: 12750.54 | P20: =P3 -> Brazil | Q20: =Q3 -> 39438.44
G21: 20 | H21: 19691.76 | P21: =P4 -> Ethiopia | Q21: =Q4 -> 39653.93
G22: 21 | H22: 19171.71 | P22: =P5 -> France | Q22: =Q5 -> 14337.4
G23: 22 | H23: 11617.86 | P23: =P6 -> Germany | Q23: =Q6 -> 16810.72
G24: 23 | H24: 17000.62 | P24: =P7 -> India | Q24: =Q7 -> 452995.44
G25: 24 | H25: 15273.35 | P25: =P8 -> Indonesia | Q25: =Q8 -> 8394.32
G26: 25 | H26: 23043.47 | P26: =P9 -> Mexico | Q26: =Q9 -> 65776.76
G27: 26 | H27: 13593.79 | P27: =P10 -> Nigeria | Q27: =Q10 -> 39993.27
G28: 27 | H28: 13197.89 | P28: =P11 -> Pakistan | Q28: =Q11 -> 77523.28
G29: 28 | H29: 13311.34 | P29: =P12 -> Russia | Q29: =Q12 -> 63344.34
G30: 29 | H30: 26662.81 | P30: =P13 -> Saudi Arabia | Q30: =Q13 -> 38317.79
... G33: 32 | H33: 6991.1 | P33: =P16 -> United States of America | Q33: =Q16 -> 13092.08
G34: 33 | H34: 17406.18
G35: 34 | H35: 10403.35
G36: 35 | H36: 29524.29
G37: 36 | H37: 14336.82
G38: 37 | H38: 15584.3
G39: 38 | H39: 13437.32
G40: 39 | H40: 30057.11
G41: 40 | H41: 17799.13
G42: 41 | H42: 25449.57
...

Sheet Dashboard

Sheet Target
A1: Month | B1: Month Name | C1: Target ($) | D1: Actual | E1: Below | F1: Above
A2: 1 | B2: Jan | C2: 90000 | D2: =VLOOKUP(TargetData[[#This Row],[Month Name]],Analysis!D1:E46,2,0) -> 92118.79 | E2: =IF(TargetData[[#This Row],[Actual]]<TargetData[[#This Row],[Target ($)]],TargetData[[#This Row],[Actual]],NA()) -> #N/A | F2: =IF(TargetData[[#This Row],[Actual]]>=TargetData[[#This Row],[Target ($)]],TargetData[[#This Row],[Actual]],NA()) -> 92118.79
A3: 2 | B3: Feb | C3: 100000 | D3: =VLOOKUP(TargetData[[#This Row],[Month Name]],Analysis!D2:E47,2,0) -> 91137.05 | E3: =IF(TargetData[[#This Row],[Actual]]<TargetData[[#This Row],[Target ($)]],TargetData[[#This Row],[Actual]],NA()) -> 91137.05 | F3: =IF(TargetData[[#This Row],[Actual]]>=TargetData[[#This Row],[Target ($)]],TargetData[[#This Row],[Actual]],NA()) -> #N/A
A4: 3 | B4: Mar | C4: 100000 | D4: =VLOOKUP(TargetData[[#This Row],[Month Name]],Analysis!D3:E48,2,0) -> 97920.72 | E4: =IF(TargetData[[#This Row],[Actual]]<TargetData[[#This Row],[Target ($)]],TargetData[[#This Row],[Actual]],NA()) -> 97920.72 | F4: =IF(TargetData[[#This Row],[Actual]]>=TargetData[[#This Row],[Target ($)]],TargetData[[#This Row],[Actual]],NA()) -> #N/A
A5: 4 | B5: Apr | C5: 100000 | D5: =VLOOKUP(TargetData[[#This Row],[Month Name]],Analysis!D4:E49,2,0) -> 72320.89 | E5: =IF(TargetData[[#This Row],[Actual]]<TargetData[[#This Row],[Target ($)]],TargetData[[#This Row],[Actual]],NA()) -> 72320.89 | F5: =IF(TargetData[[#This Row],[Actual]]>=TargetData[[#This Row],[Target ($)]],TargetData[[#This Row],[Actual]],NA()) -> #N/A
A6: 5 | B6: May | C6: 90000 | D6: =VLOOKUP(TargetData[[#This Row],[Month Name]],Analysis!D5:E50,2,0) -> 70511.76 | E6: =IF(TargetData[[#This Row],[Actual]]<TargetData[[#This Row],[Target ($)]],TargetData[[#This Row],[Actual]],NA()) -> 70511.76 | F6: =IF(TargetData[[#This Row],[Actual]]>=TargetData[[#This Row],[Target ($)]],TargetData[[#This Row],[Actual]],NA()) -> #N/A
A7: 6 | B7: Jun | C7: 90000 | D7: =VLOOKUP(TargetData[[#This Row],[Month Name]],Analysis!D6:E51,2,0) -> 66727.4 | E7: =IF(TargetData[[#This Row],[Actual]]<TargetData[[#This Row],[Target ($)]],TargetData[[#This Row],[Actual]],NA()) -> 66727.4 | F7: =IF(TargetData[[#This Row],[Actual]]>=TargetData[[#This Row],[Target ($)]],TargetData[[#This Row],[Actual]],NA()) -> #N/A
A8: 7 | B8: Jul | C8: 90000 | D8: =VLOOKUP(TargetData[[#This Row],[Month Name]],Analysis!D7:E52,2,0) -> 92661.55 | E8: =IF(TargetData[[#This Row],[Actual]]<TargetData[[#This Row],[Target ($)]],TargetData[[#This Row],[Actual]],NA()) -> #N/A | F8: =IF(TargetData[[#This Row],[Actual]]>=TargetData[[#This Row],[Target ($)]],TargetData[[#This Row],[Actual]],NA()) -> 92661.55
A9: 8 | B9: Aug | C9: 90000 | D9: =VLOOKUP(TargetData[[#This Row],[Month Name]],Analysis!D8:E53,2,0) -> 69125.75 | E9: =IF(TargetData[[#This Row],[Actual]]<TargetData[[#This Row],[Target ($)]],TargetData[[#This Row],[Actual]],NA()) -> 69125.75 | F9: =IF(TargetData[[#This Row],[Actual]]>=TargetData[[#This Row],[Target ($)]],TargetData[[#This Row],[Actual]],NA()) -> #N/A
A10: 9 | B10: Sep | C10: 90000 | D10: =VLOOKUP(TargetData[[#This Row],[Month Name]],Analysis!D9:E54,2,0) -> 78253.53 | E10: =IF(TargetData[[#This Row],[Actual]]<TargetData[[#This Row],[Target ($)]],TargetData[[#This Row],[Actual]],NA()) -> 78253.53 | F10: =IF(TargetData[[#This Row],[Actual]]>=TargetData[[#This Row],[Target ($)]],TargetData[[#This Row],[Actual]],NA()) -> #N/A
A11: 10 | B11: Oct | C11: 80000 | D11: =VLOOKUP(TargetData[[#This Row],[Month Name]],Analysis!D10:E55,2,0) -> 87136.37 | E11: =IF(TargetData[[#This Row],[Actual]]<TargetData[[#This Row],[Target ($)]],TargetData[[#This Row],[Actual]],NA()) -> #N/A | F11: =IF(TargetData[[#This Row],[Actual]]>=TargetData[[#This Row],[Target ($)]],TargetData[[#This Row],[Actual]],NA()) -> 87136.37
A12: 11 | B12: Nov | C12: 80000 | D12: =VLOOKUP(TargetData[[#This Row],[Month Name]],Analysis!D11:E56,2,0) -> 75659.86 | E12: =IF(TargetData[[#This Row],[Actual]]<TargetData[[#This Row],[Target ($)]],TargetData[[#This Row],[Actual]],NA()) -> 75659.86 | F12: =IF(TargetData[[#This Row],[Actual]]>=TargetData[[#This Row],[Target ($)]],TargetData[[#This Row],[Actual]],NA()) -> #N/A
A13: 12 | B13: Dec | C13: 80000 | D13: =VLOOKUP(TargetData[[#This Row],[Month Name]],Analysis!D12:E57,2,0) -> 90997.39 | E13: =IF(TargetData[[#This Row],[Actual]]<TargetData[[#This Row],[Target ($)]],TargetData[[#This Row],[Actual]],NA()) -> #N/A | F13: =IF(TargetData[[#This Row],[Actual]]>=TargetData[[#This Row],[Target ($)]],TargetData[[#This Row],[Actual]],NA()) -> 90997.39

Sheet Customer
A1: Customer Name | B1: Country | C1: Region
A2: Customer01 | B2: Nigeria | C2: Export
A3: Customer02 | B3: Bangladesh | C3: Export
A4: Customer03 | B4: India | C4: Northeast
A5: Customer04 | B5: Saudi Arabia | C5: Export
A6: Customer05 | B6: India | C6: Northeast
A7: Customer06 | B7: Pakistan | C7: Export
A8: Customer07 | B8: Indonesia | C8: Export
A9: Customer08 | B9: United Kingdom | C9: Export
A10: Customer09 | B10: Russia | C10: Export
A11: Customer10 | B11: India | C11: South
A12: Customer11 | B12: Mexico | C12: Export
... A41: Customer40 | B41: United States of America | C41: Export
